Workbook

Sheet nv
B1: 资产比较策略净值 | C1: 万得全A净值 | D1: 资产比较策略净值 | E1: 万得全A净值 | F1: 超额收益(右轴)
A2: 39416 | B2: 1 | C2: =[1]!i_dq_close("881001.WI",A2) -> 3359.5952
A3: 39447 | B3: 1 | C3: =[1]!i_dq_close("881001.WI",A3) -> 3858.7986
A4: 39478 | B4: 1 | C4: =[1]!i_dq_close("881001.WI",A4) -> 3430.9375
A5: 39507 | B5: 1 | C5: =[1]!i_dq_close("881001.WI",A5) -> 3548.4241
A6: 39538 | B6: 1 | C6: =[1]!i_dq_close("881001.WI",A6) -> 2870.1191
A7: 39568 | B7: 1 | C7: =[1]!i_dq_close("881001.WI",A7) -> 2946.6946
A8: 39599 | B8: 1 | C8: =[1]!i_dq_close("881001.WI",A8) -> 2724.3125
A9: 39629 | B9: 1 | C9: =[1]!i_dq_close("881001.WI",A9) -> 2113.6631
A10: 39660 | B10: 1 | C10: =[1]!i_dq_close("881001.WI",A10) -> 2178.0352
A11: 39691 | B11: 1 | C11: =[1]!i_dq_close("881001.WI",A11) -> 1805.5679
A12: 39721 | B12: 1 | C12: =[1]!i_dq_close("881001.WI",A12) -> 1686.1022
A13: 39752 | B13: 1 | C13: =[1]!i_dq_close("881001.WI",A13) -> 1251.954
... A15: 39813 | B15: 1 | C15: =[1]!i_dq_close("881001.WI",A15) -> 1430.793
A16: 39844 | B16: 1 | C16: =[1]!i_dq_close("881001.WI",A16) -> 1618.8582 | D16: =B16/B$16 -> 1 | E16: =C16/C$16 -> 1 | F16: 0
A17: 39872 | B17: 1.0496448 | C17: =[1]!i_dq_close("881001.WI",A17) -> 1711.6703 | D17: =B17/B$16 -> 1.0496448 | E17: =C17/C$16 -> 1.0573318 | F17: =(F16+1)*(B17/B16-C17/C16+1)-1 -> -0.0076870165 | G17: =IF(F17>F16,1,0) -> 0
A18: 39903 | B18: 1.266979 | C18: =[1]!i_dq_close("881001.WI",A18) -> 2026.4078 | D18: =B18/B$16 -> 1.266979 | E18: =C18/C$16 -> 1.2517513 | F18: =(F17+1)*(B18/B17-C18/C17+1)-1 -> 0.0153124 | G18: =IF(F18>F17,1,0) -> 1 | L18: 年化收益
A19: 39933 | B19: 1.4974465 | C19: =[1]!i_dq_close("881001.WI",A19) -> 2126.0664 | D19: =B19/B$16 -> 1.4974465 | E19: =C19/C$16 -> 1.3133123 | F19: =(F18+1)*(B19/B18-C19/C18+1)-1 -> 0.15006798 | G19: =IF(F19>F18,1,0) -> 1 | L19: =B219^(12/203)-1 -> 0.27445626
A20: 39964 | B20: 1.5380247 | C20: =[1]!i_dq_close("881001.WI",A20) -> 2241.2397 | D20: =B20/B$16 -> 1.5380247 | E20: =C20/C$16 -> 1.3844571 | F20: =(F19+1)*(B20/B19-C20/C19+1)-1 -> 0.11893133 | G20: =IF(F20>F19,1,0) -> 0
A21: 39994 | B21: 1.5539719 | C21: =[1]!i_dq_close("881001.WI",A21) -> 2500.6418 | D21: =B21/B$16 -> 1.5539719 | E21: =C21/C$16 -> 1.5446948 | F21: =(F20+1)*(B21/B20-C21/C20+1)-1 -> 0.0010274474 | G21: =IF(F21>F20,1,0) -> 0 | M21: 资产比较策略 | N21: 万得全A | O21: 超额收益
A22: 40025 | B22: 1.9608204 | C22: =[1]!i_dq_close("881001.WI",A22) -> 2907.0378 | D22: =B22/B$16 -> 1.9608204 | E22: =C22/C$16 -> 1.7957334 | F22: =(F21+1)*(B22/B21-C22/C21+1)-1 -> 0.1004248 | G22: =IF(F22>F21,1,0) -> 1 | L22: 2009 | M22: =B27/B16-1 -> 1.3261955 | N22: =C27/C16-1 -> 0.81596319 | O22: =M22-N22 -> 0.51023228
A23: 40056 | B23: 1.6836461 | C23: =[1]!i_dq_close("881001.WI",A23) -> 2290.3669 | D23: =B23/B$16 -> 1.6836461 | E23: =C23/C$16 -> 1.4148039 | F23: =(F22+1)*(B23/B22-C23/C22+1)-1 -> 0.17830631 | G23: =IF(F23>F22,1,0) -> 1 | L23: 2010 | M23: =B39/B27-1 -> 0.073504159 | N23: =C39/C27-1 -> -0.068786721 | O23: =M23-N23 -> 0.14229088
A24: 40086 | B24: 1.8227286 | C24: =[1]!i_dq_close("881001.WI",A24) -> 2406.5757 | D24: =B24/B$16 -> 1.8227286 | E24: =C24/C$16 -> 1.4865883 | F24: =(F23+1)*(B24/B23-C24/C23+1)-1 -> 0.21585872 | G24: =IF(F24>F23,1,0) -> 1 | L24: 2011 | M24: =B51/B39-1 -> -0.33098392 | N24: =C51/C39-1 -> -0.22418273 | O24: =M24-N24 -> -0.10680119
A25: 40117 | B25: 2.0177385 | C25: =[1]!i_dq_close("881001.WI",A25) -> 2631.8694 | D25: =B25/B$16 -> 2.0177385 | E25: =C25/C$16 -> 1.6257566 | F25: =(F24+1)*(B25/B24-C25/C24+1)-1 -> 0.23211726 | G25: =IF(F25>F24,1,0) -> 1 | L25: 2012 | M25: =B63/B51-1 -> 0.047195231 | N25: =C63/C51-1 -> 0.046795612 | O25: =M25-N25 -> 0.00039961985
A26: 40147 | B26: 2.2947199 | C26: =[1]!i_dq_close("881001.WI",A26) -> 2855.1345 | D26: =B26/B$16 -> 2.2947199 | E26: =C26/C$16 -> 1.7636718 | F26: =(F25+1)*(B26/B25-C26/C25+1)-1 -> 0.29673173 | G26: =IF(F26>F25,1,0) -> 1 | L26: 2013 | M26: =B75/B63-1 -> 0.40996924 | N26: =C75/C63-1 -> 0.054405732 | O26: =M26-N26 -> 0.35556351
A27: 40178 | B27: 2.3261955 | C27: =[1]!i_dq_close("881001.WI",A27) -> 2939.7869 | D27: =B27/B$16 -> 2.3261955 | E27: =C27/C$16 -> 1.8159632 | F27: =(F26+1)*(B27/B26-C27/C26+1)-1 -> 0.27607131 | G27: =IF(F27>F26,1,0) -> 0 | L27: 2014 | M27: =B87/B75-1 -> 0.47946684 | N27: =C87/C75-1 -> 0.52439488 | O27: =M27-N27 -> -0.044928039
A28: 40209 | B28: 2.1521625 | C28: =[1]!i_dq_close("881001.WI",A28) -> 2687.7942 | D28: =B28/B$16 -> 2.1521625 | E28: =C28/C$16 -> 1.6603024 | F28: =(F27+1)*(B28/B27-C28/C27+1)-1 -> 0.28998508 | G28: =IF(F28>F27,1,0) -> 1 | L28: 2015 | M28: =B99/B87-1 -> 0.54626132 | N28: =C99/C87-1 -> 0.38497842 | O28: =M28-N28 -> 0.16128291
A29: 40237 | B29: 2.3211604 | C29: =[1]!i_dq_close("881001.WI",A29) -> 2771.115 | D29: =B29/B$16 -> 2.3211604 | E29: =C29/C$16 -> 1.7117713 | F29: =(F28+1)*(B29/B28-C29/C28+1)-1 -> 0.35129162 | G29: =IF(F29>F28,1,0) -> 1 | L29: 2016 | M29: =B111/B99-1 -> -0.14326062 | N29: =C111/C99-1 -> -0.129106 | O29: =M29-N29 -> -0.014154621
A30: 40268 | B30: 2.3333501 | C30: =[1]!i_dq_close("881001.WI",A30) -> 2841.9175 | D30: =B30/B$16 -> 2.3333501 | E30: =C30/C$16 -> 1.7555074 | F30: =(F29+1)*(B30/B29-C30/C29+1)-1 -> 0.32386227 | G30: =IF(F30>F29,1,0) -> 0 | L30: 2017 | M30: =B123/B111-1 -> 0.31520854 | N30: =C123/C111-1 -> 0.049300843 | O30: =M30-N30 -> 0.2659077
A31: 40298 | B31: 2.2149571 | C31: =[1]!i_dq_close("881001.WI",A31) -> 2623.2981 | D31: =B31/B$16 -> 2.2149571 | E31: =C31/C$16 -> 1.6204619 | F31: =(F30+1)*(B31/B30-C31/C30+1)-1 -> 0.35853052 | G31: =IF(F31>F30,1,0) -> 1 | L31: 2018 | M31: =B135/B123-1 -> -0.21388595 | N31: =C135/C123-1 -> -0.28253486 | O31: =M31-N31 -> 0.06864891
A32: 40329 | B32: 2.0451267 | C32: =[1]!i_dq_close("881001.WI",A32) -> 2405.4834 | D32: =B32/B$16 -> 2.0451267 | E32: =C32/C$16 -> 1.4859136 | F32: =(F31+1)*(B32/B31-C32/C31+1)-1 -> 0.36716604 | G32: =IF(F32>F31,1,0) -> 1 | L32: 2019 | M32: =B147/B135-1 -> 0.40636836 | N32: =C147/C135-1 -> 0.33024003 | O32: =M32-N32 -> 0.076128328
A33: 40359 | B33: 1.9079085 | C33: =[1]!i_dq_close("881001.WI",A33) -> 2221.4492 | D33: =B33/B$16 -> 1.9079085 | E33: =C33/C$16 -> 1.3722321 | F33: =(F32+1)*(B33/B32-C33/C32+1)-1 -> 0.38003233 | G33: =IF(F33>F32,1,0) -> 1 | L33: 2020 | M33: =B159/B147-1 -> 0.69410606 | N33: =C159/C147-1 -> 0.25615885 | O33: =M33-N33 -> 0.43794721
A34: 40390 | B34: 2.1530862 | C34: =[1]!i_dq_close("881001.WI",A34) -> 2485.0549 | D34: =B34/B$16 -> 2.1530862 | E34: =C34/C$16 -> 1.5350664 | F34: =(F33+1)*(B34/B33-C34/C33+1)-1 -> 0.39361485 | G34: =IF(F34>F33,1,0) -> 1 | L34: 2021 | M34: =B171/B159-1 -> 0.4712952 | N34: =C171/C159-1 -> 0.091697406 | O34: =M34-N34 -> 0.3795978
A35: 40421 | B35: 2.2577012 | C35: =[1]!i_dq_close("881001.WI",A35) -> 2548.1951 | D35: =B35/B$16 -> 2.2577012 | E35: =C35/C$16 -> 1.5740694 | F35: =(F34+1)*(B35/B34-C35/C34+1)-1 -> 0.42591938 | G35: =IF(F35>F34,1,0) -> 1 | L35: 2022 | M35: =B183/B171-1 -> 0.43537772 | N35: =C183/C171-1 -> -0.1865536 | O35: =M35-N35 -> 0.62193133
A36: 40451 | B36: 2.332854 | C36: =[1]!i_dq_close("881001.WI",A36) -> 2575.3315 | D36: =B36/B$16 -> 2.332854 | E36: =C36/C$16 -> 1.590832 | F36: =(F35+1)*(B36/B35-C36/C35+1)-1 -> 0.45819943 | G36: =IF(F36>F35,1,0) -> 1 | L36: 2023 | M36: =B195/B183-1 -> 0.050904201 | N36: =C195/C183-1 -> -0.051906442 | O36: =M36-N36 -> 0.10281064
A37: 40482 | B37: 2.6887744 | C37: =[1]!i_dq_close("881001.WI",A37) -> 2884.6086 | D37: =B37/B$16 -> 2.6887744 | E37: =C37/C$16 -> 1.7818785 | F37: =(F36+1)*(B37/B36-C37/C36+1)-1 -> 0.50555665 | G37: =IF(F37>F36,1,0) -> 1 | L37: 2024 | M37: =B207/B195-1 -> 0.62027759 | N37: =C207/C195-1 -> 0.10003527 | O37: =M37-N37 -> 0.52024232
A38: 40512 | B38: 2.6372528 | C38: =[1]!i_dq_close("881001.WI",A38) -> 2762.1379 | D38: =B38/B$16 -> 2.6372528 | E38: =C38/C$16 -> 1.706226 | F38: =(F37+1)*(B38/B37-C38/C37+1)-1 -> 0.54062843 | G38: =IF(F38>F37,1,0) -> 1 | L38: 2025 | M38: =B219/B207-1 -> 0.41269275 | N38: =C219/C207-1 -> 0.27646743 | O38: =M38-N38 -> 0.13622532
A39: 40543 | B39: 2.4971805 | C39: =[1]!i_dq_close("881001.WI",A39) -> 2737.5686 | D39: =B39/B$16 -> 2.4971805 | E39: =C39/C$16 -> 1.691049 | F39: =(F38+1)*(B39/B38-C39/C38+1)-1 -> 0.47250501 | G39: =IF(F39>F38,1,0) -> 0
A40: 40574 | B40: 2.5837713 | C40: =[1]!i_dq_close("881001.WI",A40) -> 2681.9158 | D40: =B40/B$16 -> 2.5837713 | E40: =C40/C$16 -> 1.6566712 | F40: =(F39+1)*(B40/B39-C40/C39+1)-1 -> 0.5534997 | G40: =IF(F40>F39,1,0) -> 1
A41: 40602 | B41: 2.7301257 | C41: =[1]!i_dq_close("881001.WI",A41) -> 2824.3621 | D41: =B41/B$16 -> 2.7301257 | E41: =C41/C$16 -> 1.7446631 | F41: =(F40+1)*(B41/B40-C41/C40+1)-1 -> 0.55898367 | G41: =IF(F41>F40,1,0) -> 1
...

Sheet select
B1: 预期成长 | C1: 实际成长 | D1: 盈利能力 | E1: 质量红利 | F1: 价值红利 | G1: 破产价值 | L1: 预期成长 | M1: 实际成长 | N1: 盈利能力 | O1: 质量红利 | P1: 价值红利 | Q1: 破产价值
A2: 39447 | B2: 0 | C2: 1 | D2: 0 | E2: 0 | F2: 0 | G2: 0 | K2: 44957 | L2: 1 | M2: 0 | N2: 0 | O2: 0 | P2: 0 | Q2: 0
A3: 39478 | B3: 0 | C3: 1 | D3: 0 | E3: 0 | F3: 0 | G3: 0 | K3: 44985 | L3: 1 | M3: 0 | N3: 0 | O3: 0 | P3: 0 | Q3: 0
A4: 39507 | B4: 0 | C4: 1 | D4: 0 | E4: 0 | F4: 0 | G4: 0 | K4: 45016 | L4: 1 | M4: 0 | N4: 0 | O4: 0 | P4: 0 | Q4: 0
A5: 39538 | B5: 0 | C5: 0 | D5: 0 | E5: 0 | F5: 0 | G5: 1 | K5: 45046 | L5: 1 | M5: 0 | N5: 0 | O5: 0 | P5: 0 | Q5: 0
A6: 39568 | B6: 0 | C6: 1 | D6: 0 | E6: 0 | F6: 0 | G6: 0 | K6: 45077 | L6: 1 | M6: 1 | N6: 0 | O6: 0 | P6: 0 | Q6: 0
A7: 39599 | B7: 0 | C7: 0 | D7: 0 | E7: 0 | F7: 0 | G7: 1 | K7: 45107 | L7: 1 | M7: 1 | N7: 0 | O7: 0 | P7: 0 | Q7: 0
A8: 39629 | B8: 0 | C8: 0 | D8: 0 | E8: 0 | F8: 0 | G8: 1 | K8: 45138 | L8: 1 | M8: 1 | N8: 0 | O8: 0 | P8: 0 | Q8: 0
A9: 39660 | B9: 0 | C9: 0 | D9: 0 | E9: 0 | F9: 0 | G9: 1 | K9: 45169 | L9: 1 | M9: 1 | N9: 0 | O9: 0 | P9: 0 | Q9: 0
A10: 39691 | B10: 0 | C10: 1 | D10: 0 | E10: 0 | F10: 0 | G10: 0 | K10: 45199 | L10: 1 | M10: 0 | N10: 0 | O10: 0 | P10: 0 | Q10: 0
A11: 39721 | B11: 0 | C11: 0 | D11: 0 | E11: 0 | F11: 0 | G11: 1 | K11: 45230 | L11: 0 | M11: 0 | N11: 0 | O11: 1 | P11: 0 | Q11: 0
A12: 39752 | B12: 0 | C12: 0 | D12: 0 | E12: 0 | F12: 0 | G12: 1 | K12: 45260 | L12: 0 | M12: 0 | N12: 0 | O12: 1 | P12: 0 | Q12: 0
A13: 39782 | B13: 0 | C13: 0 | D13: 0 | E13: 0 | F13: 0 | G13: 1 | K13: 45291 | L13: 0 | M13: 0 | N13: 0 | O13: 1 | P13: 0 | Q13: 0
... A38: 40543 | B38: 0 | C38: 0 | D38: 0 | E38: 0 | F38: 1 | G38: 0 | K38: 46053 | L38: 1 | M38: 1 | N38: 1 | O38: 0 | P38: 0 | Q38: 0
A39: 40574 | B39: 0 | C39: 0 | D39: 0 | E39: 0 | F39: 1 | G39: 0
A40: 40602 | B40: 0 | C40: 0 | D40: 0 | E40: 0 | F40: 1 | G40: 0
A41: 40633 | B41: 0 | C41: 0 | D41: 0 | E41: 0 | F41: 1 | G41: 0
A42: 40663 | B42: 0 | C42: 1 | D42: 0 | E42: 0 | F42: 0 | G42: 0
A43: 40694 | B43: 0 | C43: 0 | D43: 0 | E43: 0 | F43: 1 | G43: 0
A44: 40724 | B44: 0 | C44: 0 | D44: 0 | E44: 0 | F44: 1 | G44: 0
A45: 40755 | B45: 0 | C45: 0 | D45: 0 | E45: 0 | F45: 1 | G45: 0
A46: 40786 | B46: 1 | C46: 0 | D46: 0 | E46: 0 | F46: 0 | G46: 0
A47: 40816 | B47: 1 | C47: 0 | D47: 0 | E47: 0 | F47: 0 | G47: 0
A48: 40847 | B48: 1 | C48: 0 | D48: 0 | E48: 0 | F48: 0 | G48: 0
A49: 40877 | B49: 1 | C49: 0 | D49: 0 | E49: 0 | F49: 0 | G49: 0
A50: 40908 | B50: 1 | C50: 1 | D50: 0 | E50: 0 | F50: 0 | G50: 0
... A219: 46053 | B219: 1 | C219: 1 | D219: 1 | E219: 0 | F219: 0 | G219: 0

Sheet spread_gf
B1: Top组中位数 | C1: 中位数 | D1: Botton组中位数 | E1: Top组中位数-Bottom组中位数
A2: 39082 | B2: 1.9043872 | C2: 0.61900281 | D2: 0.21901525 | E2: 1.6853719
A3: 39113 | B3: 1.9043872 | C3: 0.61900281 | D3: 0.21901525 | E3: 1.6853719
A4: 39141 | B4: 1.9043872 | C4: 0.61900281 | D4: 0.21901525 | E4: 1.6853719
A5: 39172 | B5: 1.9043872 | C5: 0.61900281 | D5: 0.21901525 | E5: 1.6853719
A6: 39202 | B6: 1.9043872 | C6: 0.61900281 | D6: 0.21901525 | E6: 1.6853719
A7: 39233 | B7: 1.9043872 | C7: 0.61900281 | D7: 0.21901525 | E7: 1.6853719
A8: 39263 | B8: 1.9043872 | C8: 0.61900281 | D8: 0.21901525 | E8: 1.6853719
A9: 39294 | B9: 1.9043872 | C9: 0.61900281 | D9: 0.21901525 | E9: 1.6853719
A10: 39325 | B10: 1.9043872 | C10: 0.61900281 | D10: 0.21901525 | E10: 1.6853719
A11: 39355 | B11: 1.9043872 | C11: 0.61900281 | D11: 0.21901525 | E11: 1.6853719
A12: 39386 | B12: 1.9043872 | C12: 0.61900281 | D12: 0.21901525 | E12: 1.6853719
A13: 39416 | B13: 1.9043872 | C13: 0.61900281 | D13: 0.21901525 | E13: 1.6853719
... A230: 46022 | B230: 2.3236382 | C230: 0.4482117 | D230: 0.11926611 | E230: 2.2043721

Sheet spread_g
B1: Top组中位数 | C1: 中位数 | D1: Botton组中位数 | E1: Top组中位数-Bottom组中位数
A2: 39082 | B2: 0.78359797 | C2: -0.013335292 | D2: -1.3904883 | E2: 2.1740862
A3: 39113 | B3: 0.78359797 | C3: -0.013335292 | D3: -1.3904883 | E3: 2.1740862
A4: 39141 | B4: 0.78359797 | C4: -0.013335292 | D4: -1.3904883 | E4: 2.1740862
A5: 39172 | B5: 0.74905474 | C5: -0.0083089367 | D5: -1.6353918 | E5: 2.3844466
A6: 39202 | B6: 1.7772637 | C6: 0.19994998 | D6: -1.3362997 | E6: 3.1135634
A7: 39233 | B7: 2.67823 | C7: 0.43824652 | D7: -0.9329388 | E7: 3.6111688
A8: 39263 | B8: 3.6296872 | C8: 0.67413427 | D8: -0.30711325 | E8: 3.9368005
A9: 39294 | B9: 3.6763462 | C9: 0.72377427 | D9: -0.21774715 | E9: 3.8940933
A10: 39325 | B10: 3.8625818 | C10: 0.81691371 | D10: -0.21151878 | E10: 4.0741005
A11: 39355 | B11: 4.2710073 | C11: 0.93687545 | D11: -0.20259384 | E11: 4.4736011
A12: 39386 | B12: 4.635853 | C12: 1.0522473 | D12: -0.16463897 | E12: 4.8004919
A13: 39416 | B13: 5.0271464 | C13: 1.1095889 | D13: -0.12762974 | E13: 5.1547761
... A230: 46022 | B230: 0.80308109 | C230: -0.027860593 | D230: -0.88476493 | E230: 1.687846

Sheet spread_ROE
B1: Top组中位数 | C1: 中位数 | D1: Botton组中位数 | E1: Top组中位数-Bottom组中位数
A2: 39082 | B2: 0.18739095 | C2: 0.064135175 | D2: -0.065758526 | E2: 0.25314948
A3: 39113 | B3: 0.18739095 | C3: 0.064135175 | D3: -0.065758526 | E3: 0.25314948
A4: 39141 | B4: 0.18739095 | C4: 0.064135175 | D4: -0.065758526 | E4: 0.25314948
A5: 39172 | B5: 0.18739095 | C5: 0.064135175 | D5: -0.065758526 | E5: 0.25314948
A6: 39202 | B6: 0.18739095 | C6: 0.064135175 | D6: -0.065758526 | E6: 0.25314948
A7: 39233 | B7: 0.18739095 | C7: 0.064135175 | D7: -0.065758526 | E7: 0.25314948
A8: 39263 | B8: 0.19920962 | C8: 0.070162419 | D8: -0.065373748 | E8: 0.26458337
A9: 39294 | B9: 0.21435249 | C9: 0.076996329 | D9: -0.06437882 | E9: 0.27873131
A10: 39325 | B10: 0.23416248 | C10: 0.087275197 | D10: -0.062439439 | E10: 0.29660192
A11: 39355 | B11: 0.25132538 | C11: 0.09796734 | D11: -0.059564549 | E11: 0.31088993
A12: 39386 | B12: 0.26140242 | C12: 0.10313848 | D12: -0.047131843 | E12: 0.30853426
A13: 39416 | B13: 0.26572217 | C13: 0.10818019 | D13: -0.036665871 | E13: 0.30238804
... A230: 46022 | B230: 0.1477859 | C230: 0.057504192 | D230: -0.041843197 | E230: 0.1896291

Sheet crowd_ROE
D1: Top组Beta因子暴露
A2: 39082 | B2: NaN | C2: NaN | D2: NaN | E2: NaN
A3: 39113 | B3: NaN | C3: NaN | D3: NaN | E3: NaN
A4: 39141 | B4: NaN | C4: NaN | D4: NaN | E4: NaN
A5: 39172 | B5: NaN | C5: NaN | D5: NaN | E5: NaN
A6: 39202 | B6: NaN | C6: NaN | D6: NaN | E6: NaN
A7: 39233 | B7: NaN | C7: NaN | D7: NaN | E7: NaN
A8: 39263 | B8: NaN | C8: NaN | D8: NaN | E8: NaN
A9: 39294 | B9: NaN | C9: NaN | D9: NaN | E9: NaN
A10: 39325 | B10: NaN | C10: NaN | D10: NaN | E10: NaN
A11: 39355 | B11: NaN | C11: NaN | D11: NaN | E11: NaN
A12: 39386 | B12: NaN | C12: NaN | D12: NaN | E12: NaN
A13: 39416 | B13: NaN | C13: NaN | D13: NaN | E13: NaN
... A26: 39813 | B26: NaN | C26: NaN | D26: NaN | E26: NaN
A27: 39844 | B27: 0.20110904 | C27: 0.16218618 | D27: 0.097693212 | E27: 0.043475313
A28: 39872 | B28: 0.16004427 | C28: 0.11699906 | D28: 0.010778834 | E28: 0.053306519
A29: 39903 | B29: 0.20149916 | C29: 0.09519873 | D29: -0.056662761 | E29: -0.033159796
A30: 39933 | B30: 0.008940226 | C30: -0.11233277 | D30: -0.27366631 | E30: 0.10538372
A31: 39964 | B31: 0.024788617 | C31: -0.11512609 | D31: -0.22025403 | E31: 0.073428448
A32: 39994 | B32: -0.015581178 | C32: -0.033938548 | D32: -0.35151552 | E32: 0.081241873
A33: 40025 | B33: -0.028974895 | C33: 0.077948736 | D33: -0.24558664 | E33: 0.18063123
A34: 40056 | B34: 0.11238693 | C34: 0.021298373 | D34: -0.18567758 | E34: 0.17830495
A35: 40086 | B35: 0.22208092 | C35: 0.1731941 | D35: -0.026606631 | E35: 0.029764556
A36: 40117 | B36: 0.23337956 | C36: 0.2846342 | D36: 0.046956269 | E36: 0.029486377
A37: 40147 | B37: 0.25007292 | C37: 0.21441757 | D37: 0.17649478 | E37: 0.029019608
A38: 40178 | B38: 0.26488174 | C38: 0.18370347 | D38: 0.17139111 | E38: 0.047527776
... A230: 46022 | B230: 0.024814796 | C230: -0.020367309 | D230: 0.091369952 | E230: -0.08874367

Sheet crowd_DP
B1: Top组近1月成交额/近3月成交额因子暴露 | D1: Top组Beta因子暴露 | F1: Top组近1月成交额/近3月成交额因子暴露
A2: 39082 | B2: NaN | C2: NaN | D2: NaN | E2: NaN
A3: 39113 | B3: NaN | C3: NaN | D3: NaN | E3: NaN
A4: 39141 | B4: NaN | C4: NaN | D4: NaN | E4: NaN
A5: 39172 | B5: NaN | C5: NaN | D5: NaN | E5: NaN
A6: 39202 | B6: NaN | C6: NaN | D6: NaN | E6: NaN
A7: 39233 | B7: NaN | C7: NaN | D7: NaN | E7: NaN
A8: 39263 | B8: NaN | C8: NaN | D8: NaN | E8: NaN
A9: 39294 | B9: NaN | C9: NaN | D9: NaN | E9: NaN
A10: 39325 | B10: NaN | C10: NaN | D10: NaN | E10: NaN
A11: 39355 | B11: NaN | C11: NaN | D11: NaN | E11: NaN
A12: 39386 | B12: NaN | C12: NaN | D12: NaN | E12: NaN
A13: 39416 | B13: NaN | C13: NaN | D13: NaN | E13: NaN
... A26: 39813 | B26: NaN | C26: NaN | D26: NaN | E26: NaN
A27: 39844 | B27: 0.09857445 | C27: -0.20759488 | D27: -0.11739232 | E27: -0.18230137 | F27: =AVERAGE(B$27:B27) -> 0.09857445
A28: 39872 | B28: 0.24102777 | C28: -0.13893037 | D28: 0.010053499 | E28: -0.09954895 | F28: =AVERAGE(B$27:B28) -> 0.16980111
A29: 39903 | B29: 0.099671271 | C29: -0.10767078 | D29: -0.017684505 | E29: -0.071479106 | F29: =AVERAGE(B27:B29) -> 0.1464245
A30: 39933 | B30: 0.11014669 | C30: -0.099948453 | D30: -0.090538594 | E30: 0.05716866 | F30: =AVERAGE(B28:B30) -> 0.15028191
A31: 39964 | B31: -0.21375349 | C31: -0.06658103 | D31: -0.12219569 | E31: -0.0052598379 | F31: =AVERAGE(B29:B31) -> -0.0013118421
A32: 39994 | B32: -0.032498967 | C32: -0.11305751 | D32: -0.26633935 | E32: 0.18192534 | F32: =AVERAGE(B30:B32) -> -0.045368588
A33: 40025 | B33: 0.0077887055 | C33: -0.088417368 | D33: -0.19457262 | E33: 0.24603018 | F33: =AVERAGE(B31:B33) -> -0.079487918
A34: 40056 | B34: -0.019847946 | C34: -0.023540963 | D34: 0.10584722 | E34: 0.23156076 | F34: =AVERAGE(B32:B34) -> -0.014852736
A35: 40086 | B35: -0.038585698 | C35: -0.0083577599 | D35: 0.0052952969 | E35: -0.033831176 | F35: =AVERAGE(B33:B35) -> -0.016881646
A36: 40117 | B36: 0.042411108 | C36: 0.08608053 | D36: 0.21024339 | E36: -0.027851977 | F36: =AVERAGE(B34:B36) -> -0.0053408452
A37: 40147 | B37: 0.052137618 | C37: -0.0045899448 | D37: 0.28143145 | E37: -0.013120789 | F37: =AVERAGE(B35:B37) -> 0.018654343
A38: 40178 | B38: 0.069386151 | C38: 0.040795586 | D38: 0.37321312 | E38: -0.023077165 | F38: =AVERAGE(B36:B38) -> 0.054644959
A39: 40209 | B39: 0.17356344 | C39: 0.1749978 | D39: 0.31694087 | E39: 0.034871868 | F39: =AVERAGE(B37:B39) -> 0.098362402
A40: 40237 | B40: 0.058274927 | C40: 0.18865732 | D40: 0.2700505 | E40: 0.047850539 | F40: =AVERAGE(B38:B40) -> 0.10040817
... A230: 46022 | B230: -0.046859024 | C230: 0.010489624 | D230: 0.16063221 | E230: 0.098590273 | F230: =AVERAGE(B228:B230) -> 0.18396672

Sheet nv_stra
B1: 预期成长策略 | C1: 实际成长策略 | D1: 盈利能力策略 | E1: 质量红利策略 | F1: 价值红利策略 | G1: 破产价值策略 | I1: 预期成长策略 | J1: 实际成长策略 | K1: 盈利能力策略 | L1: 质量红利策略 | M1: 价值红利策略 | N1: 破产价值策略 | O1: 万得全A
A2: 39416 | B2: 1 | C2: 1 | D2: 1 | E2: 1 | F2: 1 | G2: 1 | H2: 1
A3: 39447 | B3: 1 | C3: 1 | D3: 1 | E3: 1 | F3: 1 | G3: 1 | H3: 1.1806176
A4: 39478 | B4: 1 | C4: 1 | D4: 1 | E4: 1 | F4: 1 | G4: 1 | H4: 1.0859727
A5: 39507 | B5: 1 | C5: 1 | D5: 1 | E5: 1 | F5: 1 | G5: 1 | H5: 1.1464301
A6: 39538 | B6: 1 | C6: 1 | D6: 0.76808449 | E6: 1 | F6: 1 | G6: 1 | H6: 0.91174924
A7: 39568 | B7: 1 | C7: 1 | D7: 0.80183881 | E7: 1 | F7: 1 | G7: 1 | H7: 0.90979566
A8: 39599 | B8: 1 | C8: 1 | D8: 0.7306321 | E8: 1 | F8: 1 | G8: 1 | H8: 0.85901109
A9: 39629 | B9: 1 | C9: 1 | D9: 0.57174484 | E9: 1 | F9: 1 | G9: 1 | H9: 0.66426206
A10: 39660 | B10: 1 | C10: 1 | D10: 0.62351652 | E10: 1 | F10: 1 | G10: 1 | H10: 0.70571226
A11: 39691 | B11: 1 | C11: 1 | D11: 0.49439531 | E11: 1 | F11: 1 | G11: 1 | H11: 0.55976522
A12: 39721 | B12: 1 | C12: 1 | D12: 0.46909065 | E12: 1 | F12: 1 | G12: 1 | H12: 0.52284789
A13: 39752 | B13: 1 | C13: 1 | D13: 0.35282817 | E13: 1 | F13: 1 | G13: 1 | H13: 0.3843897
... A15: 39813 | B15: 1 | C15: 1 | D15: 0.43339031 | E15: 1 | F15: 1 | G15: 1 | H15: 0.46689646
A16: 39844 | B16: 1 | C16: 1 | D16: 0.53042766 | E16: 1 | F16: 1 | G16: 1 | H16: 0.54082145 | I16: =B16/B$16 -> 1 | J16: =C16/C$16 -> 1 | K16: =D16/D$16 -> 1 | L16: =E16/E$16 -> 1 | M16: =F16/F$16 -> 1 | N16: =G16/G$16 -> 1 | O16: =H16/H$16 -> 1
A17: 39872 | B17: 1.0993956 | C17: 1.0775272 | D17: 0.51558182 | E17: 1.0095057 | F17: 1.080903 | G17: 1.0793328 | H17: 0.57975102 | I17: =B17/B$16 -> 1.0993956 | J17: =C17/C$16 -> 1.0775272 | K17: =D17/D$16 -> 0.97201156 | L17: =E17/E$16 -> 1.0095057 | M17: =F17/F$16 -> 1.080903 | N17: =G17/G$16 -> 1.0793328 | O17: =H17/H$16 -> 1.0719823
A18: 39903 | B18: 1.3276603 | C18: 1.2600868 | D18: 0.62233561 | E18: 1.231459 | F18: 1.3553453 | G18: 1.3539042 | H18: 0.69756677 | I18: =B18/B$16 -> 1.3276603 | J18: =C18/C$16 -> 1.2600868 | K18: =D18/D$16 -> 1.1732714 | L18: =E18/E$16 -> 1.231459 | M18: =F18/F$16 -> 1.3553453 | N18: =G18/G$16 -> 1.3539042 | O18: =H18/H$16 -> 1.2898282
A19: 39933 | B19: 1.4826046 | C19: 1.3639842 | D19: 0.66651633 | E19: 1.4554654 | F19: 1.5148091 | G19: 1.4576789 | H19: 0.74510927 | I19: =B19/B$16 -> 1.4826046 | J19: =C19/C$16 -> 1.3639842 | K19: =D19/D$16 -> 1.2565641 | L19: =E19/E$16 -> 1.4554654 | M19: =F19/F$16 -> 1.5148091 | N19: =G19/G$16 -> 1.4576789 | O19: =H19/H$16 -> 1.3777362
A20: 39964 | B20: 1.5227806 | C20: 1.4730459 | D20: 0.67246805 | E20: 1.4033238 | F20: 1.6492114 | G20: 1.5631952 | H20: 0.77921276 | I20: =B20/B$16 -> 1.5227806 | J20: =C20/C$16 -> 1.4730459 | K20: =D20/D$16 -> 1.2677847 | L20: =E20/E$16 -> 1.4033238 | M20: =F20/F$16 -> 1.6492114 | N20: =G20/G$16 -> 1.5631952 | O20: =H20/H$16 -> 1.4407948
A21: 39994 | B21: 1.5385697 | C21: 1.5265618 | D21: 0.73333802 | E21: 1.4101696 | F21: 1.7943644 | G21: 1.6310731 | H21: 0.83998456 | I21: =B21/B$16 -> 1.5385697 | J21: =C21/C$16 -> 1.5265618 | K21: =D21/D$16 -> 1.3825411 | L21: =E21/E$16 -> 1.4101696 | M21: =F21/F$16 -> 1.7943644 | N21: =G21/G$16 -> 1.6310731 | O21: =H21/H$16 -> 1.5531643
A22: 40025 | B22: 1.9413857 | C22: 1.7435042 | D22: 0.81266456 | E22: 1.6906935 | F22: 2.1138861 | G22: 1.8411155 | H22: 0.97747135 | I22: =B22/B$16 -> 1.9413857 | J22: =C22/C$16 -> 1.7435042 | K22: =D22/D$16 -> 1.5320931 | L22: =E22/E$16 -> 1.6906935 | M22: =F22/F$16 -> 2.1138861 | N22: =G22/G$16 -> 1.8411155 | O22: =H22/H$16 -> 1.8073827
A23: 40056 | B23: 1.5981241 | C23: 1.5588672 | D23: 0.75387647 | E23: 1.5432548 | F23: 1.8520213 | G23: 1.609613 | H23: 0.81439845 | I23: =B23/B$16 -> 1.5981241 | J23: =C23/C$16 -> 1.5588672 | K23: =D23/D$16 -> 1.4212616 | L23: =E23/E$16 -> 1.5432548 | M23: =F23/F$16 -> 1.8520213 | N23: =G23/G$16 -> 1.609613 | O23: =H23/H$16 -> 1.5058545
A24: 40086 | B24: 1.7515141 | C24: 1.6667946 | D24: 0.79289101 | E24: 1.5805199 | F24: 2.0412018 | G24: 1.6698748 | H24: 0.84854981 | I24: =B24/B$16 -> 1.7515141 | J24: =C24/C$16 -> 1.6667946 | K24: =D24/D$16 -> 1.4948146 | L24: =E24/E$16 -> 1.5805199 | M24: =F24/F$16 -> 2.0412018 | N24: =G24/G$16 -> 1.6698748 | O24: =H24/H$16 -> 1.5690018
A25: 40117 | B25: 1.9749865 | C25: 1.8107852 | D25: 0.8989719 | E25: 1.8324608 | F25: 2.2326274 | G25: 1.8453952 | H25: 0.94293611 | I25: =B25/B$16 -> 1.9749865 | J25: =C25/C$16 -> 1.8107852 | K25: =D25/D$16 -> 1.6948058 | L25: =E25/E$16 -> 1.8324608 | M25: =F25/F$16 -> 2.2326274 | N25: =G25/G$16 -> 1.8453952 | O25: =H25/H$16 -> 1.7435257
A26: 40147 | B26: 2.2807041 | C26: 2.0276297 | D26: 1.0222542 | E26: 1.9744662 | F26: 2.5629054 | G26: 2.1115366 | H26: 1.0649908 | I26: =B26/B$16 -> 2.2807041 | J26: =C26/C$16 -> 2.0276297 | K26: =D26/D$16 -> 1.9272264 | L26: =E26/E$16 -> 1.9744662 | M26: =F26/F$16 -> 2.5629054 | N26: =G26/G$16 -> 2.1115366 | O26: =H26/H$16 -> 1.9692097
A27: 40178 | B27: 2.3119874 | C27: 2.1523353 | D27: 1.0584248 | E27: 2.0700951 | F27: 2.6297642 | G27: 2.1566623 | H27: 1.0841527 | I27: =B27/B$16 -> 2.3119874 | J27: =C27/C$16 -> 2.1523353 | K27: =D27/D$16 -> 1.9954178 | L27: =E27/E$16 -> 2.0700951 | M27: =F27/F$16 -> 2.6297642 | N27: =G27/G$16 -> 2.1566623 | O27: =H27/H$16 -> 2.0046407
... A219: 46022 | B219: 19.24548 | C219: 35.292429 | D219: 11.649154 | E219: 14.37607 | F219: 6.254702 | G219: 9.9417841 | H219: 2.9226669 | I219: =B219/B$16 -> 19.24548 | J219: =C219/C$16 -> 35.292429 | K219: =D219/D$16 -> 21.961815 | L219: =E219/E$16 -> 14.37607 | M219: =F219/F$16 -> 6.254702 | N219: =G219/G$16 -> 9.9417841 | O219: =H219/H$16 -> 5.4041253

Sheet recommend
B2: 预期成长策略推荐 | C2: 成分股数 | D2: 最大权重股 | E2: 平均总市值亿元 | F2: 近3月表现% | H2: 质量红利策略推荐 | I2: 成分股数 | J2: 最大权重股 | K2: 平均总市值亿元 | L2: 近3月表现% | O2: '汽车销售及服务Ⅲ' | P2: '其他家电' | Q2: '钨' | R2: '新兴金融服务Ⅱ' | S2: '锂'
A3: =[1]!to_windcode_index(B3&"(中信)") -> CI005296.WI | B3: 汽车销售及服务Ⅲ | C3: =[1]!i_info_numberofconstituents(A3) -> 5 | D3: 国机汽车 | E3: 55.28 | F3: =[1]!i_pq_pctchange(A3,$B$25,$B$26) -> -1.4761435 | G3: =[1]!to_windcode_index(H3&"(中信)") -> CI005520.WI | H3: 林木及加工 | I3: =[1]!i_info_numberofconstituents(G3) -> 4 | J3: 平潭发展 | K3: 96 | L3: =[1]!i_pq_pctchange(G3,$B$25,$B$26) -> 215.37562 | O3: '光伏设备' | P3: '电子化学品' | Q3: '航天军工' | R3: '锂电化学品' | S3: '其他家电'
A4: =[1]!to_windcode_index(B4&"(中信)") -> CI005504.WI | B4: 其他家电 | C4: =[1]!i_info_numberofconstituents(A4) -> 16 | D4: 三花智控 | E4: 204.79 | F4: =[1]!i_pq_pctchange(A4,$B$25,$B$26) -> 9.5081396 | G4: =[1]!to_windcode_index(H4&"(中信)") -> CI005271.WI | H4: 锅炉设备 | I4: =[1]!i_info_numberofconstituents(G4) -> 2 | J4: 川润股份 | K4: 69 | L4: =[1]!i_pq_pctchange(G4,$B$25,$B$26) -> 3.2276905 | O4: '白酒' | P4: '配电设备' | Q4: '种植业' | R4: '非乳饮料' | S4: '网络接配及塔设'
A5: =[1]!to_windcode_index(B5&"(中信)") -> CI005401.WI | B5: 钨 | C5: =[1]!i_info_numberofconstituents(A5) -> 4 | D5: 厦门钨业 | E5: 375.23 | F5: =[1]!i_pq_pctchange(A5,$B$25,$B$26) -> 38.372126 | G5: =[1]!to_windcode_index(H5&"(中信)") -> CI005355.WI | H5: 公交 | I5: =[1]!i_info_numberofconstituents(G5) -> 6 | J5: 大众交通 | K5: 64 | L5: =[1]!i_pq_pctchange(G5,$B$25,$B$26) -> 2.3596928 | O5: '公交' | P5: '燃料电池' | Q5: '锅炉设备' | R5: '网络接配及塔设' | S5: '林木及加工'
A6: =[1]!to_windcode_index(B6&"(中信)") -> CI005832.WI | B6: 新兴金融服务Ⅱ | C6: =[1]!i_info_numberofconstituents(A6) -> 2 | D6: 拉卡拉 | E6: 177.73 | F6: =[1]!i_pq_pctchange(A6,$B$25,$B$26) -> 21.638421 | G6: =[1]!to_windcode_index(H6&"(中信)") -> CI005480.WI | H6: 燃料电池 | I6: =[1]!i_info_numberofconstituents(G6) -> 9 | J6: 安泰科技 | K6: 112 | L6: =[1]!i_pq_pctchange(G6,$B$25,$B$26) -> 24.834119 | O6: '安防' | P6: '客车' | Q6: '日用化学品' | R6: '宠物食品' | S6: '网络接配及塔设'
A7: =[1]!to_windcode_index(B7&"(中信)") -> CI005402.WI | B7: 锂 | C7: =[1]!i_info_numberofconstituents(A7) -> 7 | D7: 赣锋锂业 | E7: 546 | F7: =[1]!i_pq_pctchange(A7,$B$25,$B$26) -> 29.108792 | G7: =[1]!to_windcode_index(H7&"(中信)") -> CI005555.WI | H7: 网络接配及塔设 | I7: =[1]!i_info_numberofconstituents(G7) -> 19 | J7: 中际旭创 | K7: 833 | L7: =[1]!i_pq_pctchange(G7,$B$25,$B$26) -> 27.746193 | O7: '汽车销售及服务Ⅲ' | P7: '棉纺制品' | Q7: '陶瓷' | R7: '印染' | S7: '建筑装修Ⅲ'
B10: 实际成长策略推荐 | C10: 成分股数 | D10: 最大权重股 | E10: 平均总市值亿元 | F10: 近3月表现% | H10: 价值红利策略推荐 | I10: 成分股数 | J10: 最大权重股 | K10: 平均总市值亿元 | L10: 近3月表现%
A11: =[1]!to_windcode_index(B11&"(中信)") -> CI005459.WI | B11: 光伏设备 | C11: =[1]!i_info_numberofconstituents(A11) -> 10 | D11: 迈为股份 | E11: 242.93 | F11: =[1]!i_pq_pctchange(A11,$B$25,$B$26) -> 4.0477555 | G11: =[1]!to_windcode_index(H11&"(中信)") -> CI005544.WI | H11: 安防 | I11: =[1]!i_info_numberofconstituents(G11) -> 18 | J11: 海康威视 | K11: 275 | L11: =[1]!i_pq_pctchange(G11,$B$25,$B$26) -> -4.3111507
A12: =[1]!to_windcode_index(B12&"(中信)") -> CI005425.WI | B12: 电子化学品 | C12: =[1]!i_info_numberofconstituents(A12) -> 24 | D12: 鼎龙股份 | E12: 136.69 | F12: =[1]!i_pq_pctchange(A12,$B$25,$B$26) -> -1.6378814 | G12: =[1]!to_windcode_index(H12&"(中信)") -> CI005252.WI | H12: 日用化学品 | I12: =[1]!i_info_numberofconstituents(G12) -> 16 | J12: 珀莱雅 | K12: 94 | L12: =[1]!i_pq_pctchange(G12,$B$25,$B$26) -> -4.8783638 | O12: 汽车销售及服务Ⅲ | P12: 光伏设备 | Q12: 白酒 | R12: 公交 | S12: 安防 | T12: 汽车销售及服务Ⅲ
A13: =[1]!to_windcode_index(B13&"(中信)") -> CI005420.WI | B13: 锂电化学品 | C13: =[1]!i_info_numberofconstituents(A13) -> 30 | D13: 天赐材料 | E13: 220 | F13: =[1]!i_pq_pctchange(A13,$B$25,$B$26) -> 13.423448 | G13: =[1]!to_windcode_index(H13&"(中信)") -> CI005523.WI | H13: 宠物食品 | I13: =[1]!i_info_numberofconstituents(G13) -> 3 | J13: 中宠股份 | K13: 154 | L13: =[1]!i_pq_pctchange(G13,$B$25,$B$26) -> -15.103585 | O13: 其他家电 | P13: 电子化学品 | Q13: 配电设备 | R13: 燃料电池 | S13: 客车 | T13: 棉纺制品
A14: =[1]!to_windcode_index(B14&"(中信)") -> CI005288.WI | B14: 航天军工 | C14: =[1]!i_info_numberofconstituents(A14) -> 17 | D14: 中国卫星 | E14: 428.6 | F14: =[1]!i_pq_pctchange(A14,$B$25,$B$26) -> 51.60521 | G14: =[1]!to_windcode_index(H14&"(中信)") -> CI005293.WI | H14: 客车 | I14: =[1]!i_info_numberofconstituents(G14) -> 6 | J14: 宇通客车 | K14: 175 | L14: =[1]!i_pq_pctchange(G14,$B$25,$B$26) -> 16.993321 | O14: 钨 | P14: 航天军工 | Q14: 种植业 | R14: 锅炉设备 | S14: 日用化学品 | T14: 陶瓷
A15: =[1]!to_windcode_index(B15&"(中信)") -> CI005504.WI | B15: 其他家电 | C15: =[1]!i_info_numberofconstituents(A15) -> 16 | D15: 三花智控 | E15: 204.79 | F15: =[1]!i_pq_pctchange(A15,$B$25,$B$26) -> 9.5081396 | G15: =[1]!to_windcode_index(H15&"(中信)") -> CI005555.WI | H15: 网络接配及塔设 | I15: =[1]!i_info_numberofconstituents(G15) -> 19 | J15: 中际旭创 | K15: 833 | L15: =[1]!i_pq_pctchange(G15,$B$25,$B$26) -> 27.746193 | O15: 新兴金融服务Ⅱ | P15: 锂电化学品 | Q15: 非乳饮料 | R15: 网络接配及塔设 | S15: 宠物食品 | T15: 印染
O16: 锂 | P16: 其他家电 | Q16: 网络接配及塔设 | R16: 林木及加工 | S16: 网络接配及塔设 | T16: 建筑装修Ⅲ
B18: 盈利能力策略推荐 | C18: 成分股数 | D18: 最大权重股 | E18: 平均总市值亿元 | F18: 近3月表现% | H18: 破产价值策略推荐 | I18: 成分股数 | J18: 最大权重股 | K18: 平均总市值亿元 | L18: 近3月表现%
A19: =[1]!to_windcode_index(B19&"(中信)") -> CI005824.WI | B19: 种植业 | C19: =[1]!i_info_numberofconstituents(A19) -> 14 | D19: 万辰集团 | E19: 117 | F19: =[1]!i_pq_pctchange(A19,$B$25,$B$26) -> 10.130312 | G19: =[1]!to_windcode_index(H19&"(中信)") -> CI005296.WI | H19: 汽车销售及服务Ⅲ | I19: =[1]!i_info_numberofconstituents(G19) -> 5 | J19: 国机汽车 | K19: 55 | L19: =[1]!i_pq_pctchange(G19,$B$25,$B$26) -> -1.4761435
A20: =[1]!to_windcode_index(B20&"(中信)") -> CI005324.WI | B20: 白酒 | C20: =[1]!i_info_numberofconstituents(A20) -> 19 | D20: 贵州茅台 | E20: 1441 | F20: =[1]!i_pq_pctchange(A20,$B$25,$B$26) -> -6.3267299 | G20: =[1]!to_windcode_index(H20&"(中信)") -> CI005261.WI | H20: 陶瓷 | I20: =[1]!i_info_numberofconstituents(G20) -> 6 | J20: 东鹏控股 | K20: 46 | L20: =[1]!i_pq_pctchange(G20,$B$25,$B$26) -> 13.618768
A21: =[1]!to_windcode_index(B21&"(中信)") -> CI005473.WI | B21: 配电设备 | C21: =[1]!i_info_numberofconstituents(A21) -> 22 | D21: 正泰电器 | E21: 93 | F21: =[1]!i_pq_pctchange(A21,$B$25,$B$26) -> -2.580242 | G21: =[1]!to_windcode_index(H21&"(中信)") -> CI005386.WI | H21: 棉纺制品 | I21: =[1]!i_info_numberofconstituents(G21) -> 9 | J21: 孚日股份 | K21: 76 | L21: =[1]!i_pq_pctchange(G21,$B$25,$B$26) -> 17.695642
A22: =[1]!to_windcode_index(B22&"(中信)") -> CI005328.WI | B22: 非乳饮料 | C22: =[1]!i_info_numberofconstituents(A22) -> 7 | D22: 东鹏特饮 | E22: 304 | F22: =[1]!i_pq_pctchange(A22,$B$25,$B$26) -> -8.3352774 | G22: =[1]!to_windcode_index(H22&"(中信)") -> CI005388.WI | H22: 印染 | I22: =[1]!i_info_numberofconstituents(G22) -> 5 | J22: 航民股份 | K22: 37 | L22: =[1]!i_pq_pctchange(G22,$B$25,$B$26) -> -2.7762245
A23: =[1]!to_windcode_index(B23&"(中信)") -> CI005555.WI | B23: 网络接配及塔设 | C23: =[1]!i_info_numberofconstituents(A23) -> 19 | D23: 中际旭创 | E23: 833 | F23: =[1]!i_pq_pctchange(A23,$B$25,$B$26) -> 27.746193 | G23: =[1]!to_windcode_index(H23&"(中信)") -> CI005436.WI | H23: 建筑装修Ⅲ | I23: =[1]!i_info_numberofconstituents(G23) -> 26 | J23: 金螳螂 | K23: 44 | L23: =[1]!i_pq_pctchange(G23,$B$25,$B$26) -> 13.385278
B25: =B26-90 -> 45932
B26: 46022

Sheet Sheet1
A1: 20250630
A2: 数据集名称 | B2: 指数权重 | E2: 数据集名称 | F2: 指数权重 | I2: 数据集名称 | J2: 指数权重 | M2: 数据集名称 | N2: 指数权重 | Q2: 数据集名称 | R2: 指数权重
A3: 日期 | B3: =A1 -> 20250630 | E3: 日期 | F3: =A1 -> 20250630 | I3: 日期 | J3: =A1 -> 20250630 | M3: 日期 | N3: =A1 -> 20250630 | Q3: 日期 | R3: =A1 -> 20250630
A4: 指数Wind代码 | B4: =recommend!A3 -> CI005296.WI | E4: 指数Wind代码 | F4: =recommend!A4 -> CI005504.WI | I4: 指数Wind代码 | J4: =recommend!A5 -> CI005401.WI | M4: 指数Wind代码 | N4: =recommend!A6 -> CI005832.WI | Q4: 指数Wind代码 | R4: =recommend!A7 -> CI005402.WI
A5: wind_code | B5: sec_name | C5: i_weight | D5: =AVERAGE(D7:D1000) -> 67.56407 | E5: wind_code | F5: sec_name | G5: i_weight | H5: =AVERAGE(H7:H1000) -> 34.922026 | I5: wind_code | J5: sec_name | K5: i_weight | L5: =AVERAGE(L7:L1000) -> 24.158599 | M5: wind_code | N5: sec_name | O5: i_weight | P5: =AVERAGE(P7:P1000) -> 66.633033 | Q5: wind_code | R5: sec_name | S5: i_weight | T5: =AVERAGE(T7:T1000) -> 193.90818
A6: Wind代码 | B6: 证券名称 | C6: 权重 | D6: 市值 | E6: Wind代码 | F6: 证券名称 | G6: 权重 | H6: 市值 | I6: Wind代码 | J6: 证券名称 | K6: 权重 | L6: 市值 | M6: Wind代码 | N6: 证券名称 | O6: 权重 | P6: 市值 | Q6: Wind代码 | R6: 证券名称 | S6: 权重 | T6: 市值
A7: =[1]!wset("indexconstituent","date="&B3,"windcode="&B4,"field=wind_code,sec_name,i_weight","cols=3;rows=5") -> 000757.SZ | B7: 浩物股份 | C7: 15.8619 | D7: =[1]!s_val_mv_ard(A7,$A$1,100000000) -> 24.132039 | E7: =[1]!wset("indexconstituent","date="&F3,"windcode="&F4,"field=wind_code,sec_name,i_weight","cols=3;rows=17") -> 000404.SZ | F7: 长虹华意 | G7: 3.3452 | H7: =[1]!s_val_mv_ard(E7,$A$1,100000000) -> 49.415715 | I7: =[1]!wset("indexconstituent","date="&J3,"windcode="&J4,"field=wind_code,sec_name,i_weight","cols=3;rows=4") -> 000657.SZ | J7: 中钨高新 | K7: 25.6529 | L7: =[1]!s_val_mv_ard(I7,$A$1,100000000) -> 270.28399 | M7: =[1]!wset("indexconstituent","date="&N3,"windcode="&N4,"field=wind_code,sec_name,i_weight","cols=3;rows=2") -> 300773.SZ | N7: 拉卡拉 | O7: 76.1657 | P7: =[1]!s_val_mv_ard(M7,$A$1,100000000) -> 263.6136 | Q7: =[1]!wset("indexconstituent","date="&R3,"windcode="&R4,"field=wind_code,sec_name,i_weight","cols=3;rows=7") -> 002192.SZ | R7: 融捷股份 | S7: 4.7783 | T7: =[1]!s_val_mv_ard(Q7,$A$1,100000000) -> 79.558354
A8: 301215.SZ | B8: 中汽股份 | C8: 22.3697 | D8: =[1]!s_val_mv_ard(A8,$A$1,100000000) -> 82.0818 | E8: 002050.SZ | F8: 三花智控 | G8: 52.3965 | H8: =[1]!s_val_mv_ard(E8,$A$1,100000000) -> 1093.9177 | I8: 002378.SZ | J8: 章源钨业 | K8: 12.2473 | L8: =[1]!s_val_mv_ard(I8,$A$1,100000000) -> 95.032137 | M8: 603123.SH | N8: 翠微股份 | O8: 23.8343 | P8: =[1]!s_val_mv_ard(M8,$A$1,100000000) -> 136.1846 | Q8: 002240.SZ | R8: 盛新锂能 | S8: 7.0154 | T8: =[1]!s_val_mv_ard(Q8,$A$1,100000000) -> 117.88985
A9: 600335.SH | B9: 国机汽车 | C9: 28.6673 | D9: =[1]!s_val_mv_ard(A9,$A$1,100000000) -> 96.478371 | E9: 002290.SZ | F9: 禾盛新材 | G9: 4.1366 | H9: =[1]!s_val_mv_ard(E9,$A$1,100000000) -> 77.535103 | I9: 002842.SZ | J9: 翔鹭钨业 | K9: 5.3637 | L9: =[1]!s_val_mv_ard(I9,$A$1,100000000) -> 27.318897 | P9: =[1]!s_val_mv_ard(M9,$A$1,100000000) -> 0 | Q9: 002460.SZ | R9: 赣锋锂业 | S9: 29.4059 | T9: =[1]!s_val_mv_ard(Q9,$A$1,100000000) -> 681.19756
A10: 600653.SH | B10: 申华控股 | C10: 25.9068 | E10: 002418.SZ | F10: 康盛股份 | G10: 2.8794 | H10: =[1]!s_val_mv_ard(E10,$A$1,100000000) -> 40.3422 | I10: 600549.SH | J10: 厦门钨业 | K10: 56.7361 | L10: =[1]!s_val_mv_ard(I10,$A$1,100000000) -> 332.12295 | P10: =[1]!s_val_mv_ard(M10,$A$1,100000000) -> 0 | Q10: 002466.SZ | R10: 天齐锂业 | S10: 25.5239 | T10: =[1]!s_val_mv_ard(Q10,$A$1,100000000) -> 525.8474
A11: 605151.SH | B11: 西上海 | C11: 7.1943 | E11: 002676.SZ | F11: 顺威股份 | G11: 3.3478 | H11: =[1]!s_val_mv_ard(E11,$A$1,100000000) -> 52.056 | L11: =[1]!s_val_mv_ard(I11,$A$1,100000000) -> 0 | P11: =[1]!s_val_mv_ard(M11,$A$1,100000000) -> 0 | Q11: 002497.SZ | R11: 雅化集团 | S11: 9.0635 | T11: =[1]!s_val_mv_ard(Q11,$A$1,100000000) -> 131.39213
E12: 002860.SZ | F12: 星帅尔 | G12: 2.7874 | H12: =[1]!s_val_mv_ard(E12,$A$1,100000000) -> 47.98565 | L12: =[1]!s_val_mv_ard(I12,$A$1,100000000) -> 0 | P12: =[1]!s_val_mv_ard(M12,$A$1,100000000) -> 0 | Q12: 002738.SZ | R12: 中矿资源 | S12: 15.6087 | T12: =[1]!s_val_mv_ard(Q12,$A$1,100000000) -> 232.03179
E13: 003028.SZ | F13: 振邦智能 | G13: 1.4119 | H13: =[1]!s_val_mv_ard(E13,$A$1,100000000) -> 44.871414 | L13: =[1]!s_val_mv_ard(I13,$A$1,100000000) -> 0 | Q13: 002756.SZ | R13: 永兴材料 | S13: 8.6042 | T13: =[1]!s_val_mv_ard(Q13,$A$1,100000000) -> 171.16474
E14: 300217.SZ | F14: 东方电热 | G14: 5.0773 | H14: =[1]!s_val_mv_ard(E14,$A$1,100000000) -> 77.889385 | L14: =[1]!s_val_mv_ard(I14,$A$1,100000000) -> 0 | T14: =[1]!s_val_mv_ard(Q14,$A$1,100000000) -> 0
E15: 300279.SZ | F15: 和晶科技 | G15: 2.2431 | H15: =[1]!s_val_mv_ard(E15,$A$1,100000000) -> 33.894595 | L15: =[1]!s_val_mv_ard(I15,$A$1,100000000) -> 0 | T15: =[1]!s_val_mv_ard(Q15,$A$1,100000000) -> 0
E16: 300342.SZ | F16: 天银机电 | G16: 4.909 | H16: =[1]!s_val_mv_ard(E16,$A$1,100000000) -> 74.976194 | L16: =[1]!s_val_mv_ard(I16,$A$1,100000000) -> 0 | T16: =[1]!s_val_mv_ard(Q16,$A$1,100000000) -> 0
E17: 300403.SZ | F17: 汉宇集团 | G17: 5.3473 | H17: =[1]!s_val_mv_ard(E17,$A$1,100000000) -> 91.5957 | L17: =[1]!s_val_mv_ard(I17,$A$1,100000000) -> 0
E18: 301135.SZ | F18: 瑞德智能 | G18: 1.4643 | H18: =[1]!s_val_mv_ard(E18,$A$1,100000000) -> 27.25177 | L18: =[1]!s_val_mv_ard(I18,$A$1,100000000) -> 0
E19: 600619.SH | F19: 海立股份 | G19: 5.479 | H19: =[1]!s_val_mv_ard(E19,$A$1,100000000) -> 122.4686 | L19: =[1]!s_val_mv_ard(I19,$A$1,100000000) -> 0
E20: 603219.SH | F20: 富佳股份 | G20: 1.6588 | H20: =[1]!s_val_mv_ard(E20,$A$1,100000000) -> 81.45914 | L20: =[1]!s_val_mv_ard(I20,$A$1,100000000) -> 0
E21: 603578.SH | F21: 三星新材 | G21: 1.1182 | H21: =[1]!s_val_mv_ard(E21,$A$1,100000000) -> 25.971413 | L21: =[1]!s_val_mv_ard(I21,$A$1,100000000) -> 0
E22: 603657.SH | F22: 春光科技 | G22: 1.4034 | H22: =[1]!s_val_mv_ard(E22,$A$1,100000000) -> 45.153477 | L22: =[1]!s_val_mv_ard(I22,$A$1,100000000) -> 0
E23: 603677.SH | F23: 奇精机械 | G23: 0.9947 | H23: =[1]!s_val_mv_ard(E23,$A$1,100000000) -> 38.693514 | L23: =[1]!s_val_mv_ard(I23,$A$1,100000000) -> 0
H24: =[1]!s_val_mv_ard(E24,$A$1,100000000) -> 0 | L24: =[1]!s_val_mv_ard(I24,$A$1,100000000) -> 0
H25: =[1]!s_val_mv_ard(E25,$A$1,100000000) -> 0 | L25: =[1]!s_val_mv_ard(I25,$A$1,100000000) -> 0
H26: =[1]!s_val_mv_ard(E26,$A$1,100000000) -> 0 | L26: =[1]!s_val_mv_ard(I26,$A$1,100000000) -> 0
H27: =[1]!s_val_mv_ard(E27,$A$1,100000000) -> 0 | L27: =[1]!s_val_mv_ard(I27,$A$1,100000000) -> 0
H28: =[1]!s_val_mv_ard(E28,$A$1,100000000) -> 0 | L28: =[1]!s_val_mv_ard(I28,$A$1,100000000) -> 0
H29: =[1]!s_val_mv_ard(E29,$A$1,100000000) -> 0 | L29: =[1]!s_val_mv_ard(I29,$A$1,100000000) -> 0
H30: =[1]!s_val_mv_ard(E30,$A$1,100000000) -> 0 | L30: =[1]!s_val_mv_ard(I30,$A$1,100000000) -> 0
H31: =[1]!s_val_mv_ard(E31,$A$1,100000000) -> 0 | L31: =[1]!s_val_mv_ard(I31,$A$1,100000000) -> 0
H32: =[1]!s_val_mv_ard(E32,$A$1,100000000) -> 0 | L32: =[1]!s_val_mv_ard(I32,$A$1,100000000) -> 0
H33: =[1]!s_val_mv_ard(E33,$A$1,100000000) -> 0 | L33: =[1]!s_val_mv_ard(I33,$A$1,100000000) -> 0
H34: =[1]!s_val_mv_ard(E34,$A$1,100000000) -> 0 | L34: =[1]!s_val_mv_ard(I34,$A$1,100000000) -> 0
H35: =[1]!s_val_mv_ard(E35,$A$1,100000000) -> 0 | L35: =[1]!s_val_mv_ard(I35,$A$1,100000000) -> 0
H36: =[1]!s_val_mv_ard(E36,$A$1,100000000) -> 0 | L36: =[1]!s_val_mv_ard(I36,$A$1,100000000) -> 0
H37: =[1]!s_val_mv_ard(E37,$A$1,100000000) -> 0
H38: =[1]!s_val_mv_ard(E38,$A$1,100000000) -> 0
H39: =[1]!s_val_mv_ard(E39,$A$1,100000000) -> 0
H40: =[1]!s_val_mv_ard(E40,$A$1,100000000) -> 0
...

Sheet view
B1: 大势研判观点
B2: 综合判断占优风格：预期成长、实际成长、盈利能力 - 预期增速资产优势差继续回升，主题类成长风格继续推荐； - 实际增速资产优势差小幅回升，景气类策略宜保持标配； - ROE的优势差继续上行，拥挤度较低下，盈利能力策略可继续增配； - 高股息类资产当下的拥挤度仍高，继续不建议超配； - Δgf、Δg、ΔROE同处扩张，1月推荐预期成长+实际成长+盈利能力风格。
B3: #VALUE! | E3: #VALUE!
B6: 风格类型 | C6: 筛选逻辑 | D6: 当下推荐
B7: 预期成长 | C7: 分析师 | D7: =recommend!B3 -> 汽车销售及服务Ⅲ | E7: =recommend!B4 -> 其他家电 | F7: =recommend!B5 -> 钨 | G7: =recommend!B6 -> 新兴金融服务Ⅱ | H7: =recommend!B7 -> 锂
B8: 实际成长 | C8: 超预期 | D8: =recommend!B11 -> 光伏设备 | E8: =recommend!B12 -> 电子化学品 | F8: =recommend!B13 -> 锂电化学品 | G8: =recommend!B14 -> 航天军工 | H8: =recommend!B15 -> 其他家电
B9: 盈利能力 | C9: PB-ROE | D9: =recommend!B19 -> 种植业 | E9: =recommend!B20 -> 白酒 | F9: =recommend!B21 -> 配电设备 | G9: =recommend!B22 -> 非乳饮料 | H9: =recommend!B23 -> 网络接配及塔设
B10: 质量红利 | C10: DP+ROE | D10: =recommend!H3 -> 林木及加工 | E10: =recommend!H4 -> 锅炉设备 | F10: =recommend!H5 -> 公交 | G10: =recommend!H6 -> 燃料电池 | H10: =recommend!H7 -> 网络接配及塔设
B11: 价值红利 | C11: DP+BP | D11: =recommend!H11 -> 安防 | E11: =recommend!H12 -> 日用化学品 | F11: =recommend!H13 -> 宠物食品 | G11: =recommend!H14 -> 客车 | H11: =recommend!H15 -> 网络接配及塔设
B12: 破产价值 | C12: PB+SIZE | D12: =recommend!H19 -> 汽车销售及服务Ⅲ | E12: =recommend!H20 -> 陶瓷 | F12: =recommend!H21 -> 棉纺制品 | G12: =recommend!H22 -> 印染 | H12: =recommend!H23 -> 建筑装修Ⅲ

Sheet exp
C1: 45961 | D1: 45991 | E1: delta
A2: CI005420.WI | B2: 锂电化学品 | C2: =[1]!s_west_netprofit_cagr($A2,C$1) -> 114.6738 | D2: =[1]!s_west_netprofit_cagr($A2,D$1) -> 135.7772 | E2: =D2-C2 -> 21.1034
A3: CI005350.WI | B3: 非住宅物业开发和运营 | C3: =[1]!s_west_netprofit_cagr($A3,C$1) -> -82.9607 | D3: =[1]!s_west_netprofit_cagr($A3,D$1) -> -65.7282 | E3: =D3-C3 -> 17.2325
A4: CI005477.WI | B4: 储能 | C4: =[1]!s_west_netprofit_cagr($A4,C$1) -> 262.7058 | D4: =[1]!s_west_netprofit_cagr($A4,D$1) -> 277.0359 | E4: =D4-C4 -> 14.3301
A5: CI005555.WI | B5: 网络接配及塔设 | C5: =[1]!s_west_netprofit_cagr($A5,C$1) -> 80.7404 | D5: =[1]!s_west_netprofit_cagr($A5,D$1) -> 93.5975 | E5: =D5-C5 -> 12.8571
A6: CI005557.WI | B6: 增值服务Ⅲ | C6: =[1]!s_west_netprofit_cagr($A6,C$1) -> 7.3902 | D6: =[1]!s_west_netprofit_cagr($A6,D$1) -> 20.1208 | E6: =D6-C6 -> 12.7306
A7: CI005277.WI | B7: 船舶制造 | C7: =[1]!s_west_netprofit_cagr($A7,C$1) -> 90.8062 | D7: =[1]!s_west_netprofit_cagr($A7,D$1) -> 102.0693 | E7: =D7-C7 -> 11.2631
A8: CI005247.WI | B8: 氟化工 | C8: =[1]!s_west_netprofit_cagr($A8,C$1) -> 85.0525 | D8: =[1]!s_west_netprofit_cagr($A8,D$1) -> 96.0978 | E8: =D8-C8 -> 11.0453
A9: CI005328.WI | B9: 非乳饮料 | C9: =[1]!s_west_netprofit_cagr($A9,C$1) -> 17.7693 | D9: =[1]!s_west_netprofit_cagr($A9,D$1) -> 25.92 | E9: =D9-C9 -> 8.1507
A10: CI005842.WI | B10: 计算机设备 | C10: =[1]!s_west_netprofit_cagr($A10,C$1) -> 47.3252 | D10: =[1]!s_west_netprofit_cagr($A10,D$1) -> 55.2418 | E10: =D10-C10 -> 7.9166
A11: CI005355.WI | B11: 公交 | C11: =[1]!s_west_netprofit_cagr($A11,C$1) -> 21.5225 | D11: =[1]!s_west_netprofit_cagr($A11,D$1) -> 27.9858 | E11: =D11-C11 -> 6.4633
A12: CI005434.WI | B12: 园林工程 | C12: =[1]!s_west_netprofit_cagr($A12,C$1) -> -91.5846 | D12: =[1]!s_west_netprofit_cagr($A12,D$1) -> -85.5682 | E12: =D12-C12 -> 6.0164
A13: CI005436.WI | B13: 建筑装修Ⅲ | C13: =[1]!s_west_netprofit_cagr($A13,C$1) -> 29.389 | D13: =[1]!s_west_netprofit_cagr($A13,D$1) -> 34.7691 | E13: =D13-C13 -> 5.3801
... A203: CI005843.WI | B203: 计算机软件 | C203: =[1]!s_west_netprofit_cagr($A203,C$1) -> 246.7974 | D203: =[1]!s_west_netprofit_cagr($A203,D$1) -> 193.8436 | E203: =D203-C203 -> -52.9538
